Workbook
Name ListaContratos: '2027'!$E$8:$E$107

Sheet Instruções
A1: COMO PREENCHER — Superintendência Municipal de Distritos - SMD
A2: Guia rápido para quem alimenta os dados • Fluxo: aba 2027 → Ficha do contrato → Base de Dados → Dashboard
B4: ANTES DE COMEÇAR — ENTENDA AS CORES DAS CÉLULAS
B6: BRANCO | C6: Digitação manual — é aqui que você digita os dados.
B7: BEGE | C7: Lista suspensa — clique na célula e ESCOLHA uma opção (digitar livremente é rejeitado).
B8: AZUL CLARO | C8: Automático — preenche sozinho a partir de outra aba. Bloqueado para digitação.
B9: VERDE CLARO | C9: Calculado / alerta — resultado automático de fórmula. Bloqueado para digitação.
B11: PASSO 1 — CADASTRE O CONTRATO NA ABA «2027»
B13: • Use a primeira linha em branco da tabela (começa na linha 8). Uma linha por contrato, sem pular linhas.
B14: • Digite nas células brancas: processo SEI, contratada, CPF/CNPJ, nº do contrato/ano, objeto,
B15: datas de vigência (dd/mm/aaaa), valor mensal (apenas números, sem “R$”), meses vigentes e valor empenhado.
B16: • Escolha nas listas bege: Tipo de Objeto, Modalidade de Licitação, Regime de Execução e Tipo de Empenho.
B17: • As colunas azuis calculam sozinhas — ex.: Valor Total no Exercício = Valor Mensal × Meses Vigentes;
B18: Saldo a Empenhar = Valor Total − Valor Empenhado. A linha TOTAL, fixa no topo, soma tudo.
B20: ABA «PRETENSÕES 2027» — PLANEJAMENTO DE CONTRATAÇÕES FUTURAS
B22: • Registre as contratações que a unidade PRETENDE realizar em 2027 — uma linha por objeto pretendido.
B23: • Digite nas células brancas: objeto, quantidade, unidade de medida, valor estimado (apenas números), justificativa e observações.
B24: • Escolha nas listas bege: Tipo de Objeto, Trimestre Previsto, Grau de Prioridade e Fonte de Recursos.
B25: • A linha TOTAL, no topo, soma o valor estimado automaticamente.
... B62: EXEMPLO — competência de Julho/2027 paga por duas fontes:
B63: Período Ref. | C63: Nº Empenho | D63: Valor Pago (R$) | E63: Fonte de Recurso | F63: Observações
B64: Julho/2027 | C64: 2027NE0045 | D64: 30.000,00 | E64: Recurso Livre | F64: Parcela mensal – parte 1/2
B65: Julho/2027 | C65: 2027NE0051 | D65: 20.000,00 | E65: Convênio | F65: Parcela mensal – parte 2/2
B66: Resultado: o KPI 2.1 soma R$ 30.000 em Recurso Livre e R$ 20.000 em Convênio; o total do mês (R$ 50.000) fica correto automaticamente.
B69: GUIA RÁPIDO DAS LISTAS SUSPENSAS
B71: TIPO DE OBJETO — lista completa (selecionável nas abas 2027 e Pretensões 2027):
B72: Contratos Tradicionais de Compras e Serviços (Lei 14.133/2021)
B73: Contrato de Obras | C73: Construção, reforma ou ampliação de prédios públicos, escolas, postos de saúde e pontes.
B74: Contrato de Serviços de Engenharia | C74: Manutenção preventiva, reformas parciais, reparos asfálticos e sinalização viária.
B75: Contrato de Prestação de Serviços Contínuos | C75: Serviços essenciais do dia a dia: limpeza urbana, segurança patrimonial e TI.
B76: Contrato de Prestação de Serviços Técnicos Especializados | C76: Consultorias, auditorias externas, estudos de viabilidade ou projetos arquitetônicos.
B77: Contrato de Fornecimento Integral (Compras) | C77: Aquisição imediata ou parcelada de bens móveis (medicamentos, merenda, fardamentos, veículos).
B78: Contrato de Locação de Imóveis | C78: Aluguel de imóveis privados para abrigar secretarias, creches ou almoxarifados municipais.
B79: Contrato de Alienação | C79: Venda de bens públicos móveis inservíveis (carros velhos, sucata) ou imóveis autorizados por lei.
B81: Contratos de Concessão e Delegação de Serviços
B82: Concessão Comum de Serviço Público | C82: Serviço ao setor privado com remuneração via tarifa paga pelo usuário (ex.: transporte coletivo).
B83: Parceria Público-Privada (PPP) Administrativa | C83: Concessão em que o município é o usuário e paga integralmente (ex.: iluminação pública, hospital).
B84: Parceria Público-Privada (PPP) Patrocinada | C84: Tarifa paga pelo cidadão + complemento pago pela prefeitura (ex.: saneamento, água e esgoto).
B85: Permissão de Uso de Bem Público | C85: Uso precário de espaços públicos por particulares (ex.: quiosques, bancas, boxes de mercados).
B87: Parcerias com o Terceiro Setor (MROSC — Lei 13.019/2014)
...

Sheet 2027
A1: UNIDADE: Superintendência Municipal de Distritos - SMD
A3: CONTROLE DE CONTRATOS VIGENTES — 2027
A5: TOTAL | M5: =SUM(M8:M107) -> 93551.81 | O5: =SUM(O8:O107) -> 1101021.7 | Q5: =SUM(Q8:Q107) -> 1085331.8 | R5: =SUM(R8:R107) -> 15689.96 | T5: =SUM(T8:T107) -> 5462.32 | U5: =SUM(U8:U107) -> 18220.68
A7: Nº | B7: Nº do Processo SEI | C7: Contratada (Nome/Razão Social) | D7: CPF/CNPJ da Contratada | E7: Nº do Contrato/Ano | F7: Tipo de Objeto | G7: Modalidade de Licitação | H7: Objeto do Contrato | I7: Regime de Execução | J7: Tipo de Empenho | K7: Início da Vigência | L7: Término da Vigência | M7: Valor Mensal do Contrato | N7: Meses Vigentes no Exercício | O7: Valor Total no Exercício 2027 | P7: Meses Empenhados | Q7: Valor Empenhado no Exercício | R7: Saldo a Empenhar | S7: % Empenhado no Exercício | T7: Saldo Orçamentário da Unidade | U7: Valor a Suplementar | V7: Observações | W7: Nº Duplicado?
A8: 1 | B8: 024.000147/2025-98 | C8: RECHE GALDEANO & CIA LTDA | D8: 08.713.403/0001-90 | E8: 66/2024 | F8: Contrato de Prestação de Serviços Contínuos | G8: Carona (ARP Externa) | H8: Locação de 11 veículos utilitários leves, sem condutor, para atendimento da sede e dos distritos. | I8: Contrato continuado | J8: Global | K8: 9/26/2024 | L8: 9/26/2027 | M8: 42393.45 | N8: 12 | O8: =IFERROR(M8*N8,0) -> 508721.4 | P8: =IFERROR(ROUNDDOWN(Q8/M8,0),0) -> 12 | Q8: 508721.4 | R8: =IFERROR(O8-Q8,0) -> 0 | S8: =IFERROR(Q8/O8,0) -> 1 | T8: 19.3 | U8: =IFERROR(R8-T8,0) -> -19.3 | V8: Projeção anual para 2027. Referência de 2026: R$ 508.721,40 empenhados. O saldo de R$ 19,30 do elemento 3.3.90.33, compartilhado com o Contrato nº 64/2025, foi registrado somente nesta linha para evitar duplicidade. | W8: =IF($E8="","",IF(COUNTIF($E$8:$E$107,$E8)>1,"DUPLICADO","OK")) -> OK
A9: 2 | B9: 024.000144/2025-54 | C9: ISAIAS RODRIGUES DOS ANJOS | D9: 768.916.742-04 | E9: 39/2022 | F9: Contrato de Locação de Imóveis | G9: Dispensa | H9: Locação do imóvel onde funciona a sede administrativa do Distrito de Extrema. | I9: Contrato continuado | J9: Global | K9: 7/23/2022 | L9: 7/22/2027 | M9: 4117 | N9: 12 | O9: =IFERROR(M9*N9,0) -> 49404 | P9: =IFERROR(ROUNDDOWN(Q9/M9,0),0) -> 12 | Q9: 49721 | R9: =IFERROR(O9-Q9,0) -> -317 | S9: =IFERROR(Q9/O9,0) -> 1.0064165 | T9: 1959.02 | U9: =IFERROR(R9-T9,0) -> -2276.02 | V9: Projeção anual para 2027. Referência de 2026: R$ 49.721,00 empenhados, considerando o processo principal e o processo apartado nº 024.000319/2026-12. O saldo de R$ 1.959,02 do elemento 3.3.90.36, compartilhado com as demais locações de pessoa física, foi registrado somente nesta linha. | W9: =IF($E9="","",IF(COUNTIF($E$8:$E$107,$E9)>1,"DUPLICADO","OK")) -> OK
A10: 3 | B10: 024.000200/2025-51 | C10: HELENA VASCONCELOS DE ALENCAR | D10: 161.816.892-49 | E10: 20/2023 | F10: Contrato de Locação de Imóveis | G10: Dispensa | H10: Locação do imóvel onde funciona a sede administrativa do Distrito de Nazaré. | I10: Contrato continuado | J10: Global | K10: 4/14/2023 | L10: 4/13/2027 | M10: 1095.11 | N10: 12 | O10: =IFERROR(M10*N10,0) -> 13141.32 | P10: =IFERROR(ROUNDDOWN(Q10/M10,0),0) -> 12 | Q10: 13443.69 | R10: =IFERROR(O10-Q10,0) -> -302.37 | S10: =IFERROR(Q10/O10,0) -> 1.0230091 | T10: - | U10: =IFERROR(R10-T10,0) -> 0 | V10: Projeção anual para 2027. Referência de 2026: R$ 13.443,69 empenhados. O saldo compartilhado do elemento 3.3.90.36 foi registrado na linha do Contrato nº 39/2022 para não ser somado em duplicidade. | W10: =IF($E10="","",IF(COUNTIF($E$8:$E$107,$E10)>1,"DUPLICADO","OK")) -> OK
A11: 4 | B11: 024.000150/2025-10 | C11: FUNDO PENITENCIARIO DO ESTADO DE RONDONIA - FUPEN | D11: 15.837.081/0001-56 | E11: 92/2023 | F11: Convênio Administrativo | H11: Cooperação para disponibilização de 1 reeducando em regime aberto, em atividade de serviços gerais na SMD. | I11: Contrato continuado | J11: Estimativo | K11: 45234 | L11: 46664 | M11: 2526.25 | N11: 12 | O11: =IFERROR(M11*N11,0) -> 30315 | P11: =IFERROR(ROUNDDOWN(Q11/M11,0),0) -> 12 | Q11: 31365.67 | R11: =IFERROR(O11-Q11,0) -> -1050.67 | S11: =IFERROR(Q11/O11,0) -> 1.0346584 | T11: - | U11: =IFERROR(R11-T11,0) -> 0 | V11: Projeção anual para 2027. Referência de 2026: R$ 31.365,67 empenhados líquidos, incluída a despesa de exercício anterior vinculada ao instrumento. Não foi identificado saldo livre específico no elemento para registro nesta linha. | W11: =IF($E11="","",IF(COUNTIF($E$8:$E$107,$E11)>1,"DUPLICADO","OK")) -> OK
A12: 5 | B12: 024.000145/2025-07 | C12: IMOBILIÁRIA ATRIUM LTDA | D12: 21.309.241/0001-97 | E12: 16/2023 | F12: Contrato de Locação de Imóveis | G12: Dispensa | H12: Locação do imóvel onde funciona a sede administrativa da SMD. | I12: Contrato continuado | J12: Global | K12: 3/16/2023 | L12: 9/14/2027 | M12: 13000 | N12: 12 | O12: =IFERROR(M12*N12,0) -> 156000 | P12: =IFERROR(ROUNDDOWN(Q12/M12,0),0) -> 12 | Q12: 156000 | R12: =IFERROR(O12-Q12,0) -> 0 | S12: =IFERROR(Q12/O12,0) -> 1 | T12: 3484 | U12: =IFERROR(R12-T12,0) -> -3484 | V12: Terceiro termo aditivo: vigência por 24 meses a partir de 15/09/2025 e aluguel mensal de R$ 13.000,00. Projeção anual para 2027. Referência de 2026: R$ 156.000,00 empenhados; saldo informado no elemento 3.3.90.39: R$ 3.484,00. | W12: =IF($E12="","",IF(COUNTIF($E$8:$E$107,$E12)>1,"DUPLICADO","OK")) -> OK
A13: 6 | B13: 024.000146/2025-43 | C13: LUCAS GOMES PATRICIO | D13: 019.472.152-30 | E13: 28/2018 | F13: Contrato de Locação de Imóveis | G13: Dispensa | H13: Locação do imóvel onde funciona a sede administrativa do Distrito de União Bandeirantes. | I13: Contrato continuado | J13: Global | K13: 4/17/2018 | L13: 10/15/2026 | M13: 1200 | N13: 4 | O13: =IFERROR(M13*N13,0) -> 4800 | P13: =IFERROR(ROUNDDOWN(Q13/M13,0),0) -> 9 | Q13: 11440 | R13: =IFERROR(O13-Q13,0) -> -6640 | S13: =IFERROR(Q13/O13,0) -> 2.3833333 | T13: - | U13: =IFERROR(R13-T13,0) -> 0 | V13: Oitavo termo aditivo vigente por seis meses a partir de 16/04/2026. A necessidade foi projetada para os 12 meses de 2027, mediante nova locação ou instrumento cabível. Referência de 2026: R$ 11.440,00 empenhados. O saldo compartilhado do elemento 3.3.90.36 foi registrado na linha de Extrema. | W13: =IF($E13="","",IF(COUNTIF($E$8:$E$107,$E13)>1,"DUPLICADO","OK")) -> OK
A14: 7 | B14: 024.000050/2025-85 | C14: KAELE LTDA | D14: 04.819.323/0001-62 | E14: 64/2025 | F14: Contrato de Prestação de Serviços Contínuos | G14: Carona (ARP Externa) | H14: Locação de 2 caminhonetes 4x4, sem condutor, para deslocamentos em ramais e localidades de difícil acesso. | I14: Contrato continuado | J14: Global | K14: 45728 | L14: 46065 | M14: 26220 | N14: 12 | O14: =IFERROR(M14*N14,0) -> 314640 | P14: =IFERROR(ROUNDDOWN(Q14/M14,0),0) -> 12 | Q14: 314640 | R14: =IFERROR(O14-Q14,0) -> 0 | S14: =IFERROR(Q14/O14,0) -> 1 | T14: - | U14: =IFERROR(R14-T14,0) -> 0 | V14: Contrato com prazo de 12 meses contado da assinatura em 03/12/2025. A continuidade foi projetada para todo o exercício de 2027. Referência de 2026: R$ 314.640,00 empenhados. O saldo compartilhado do elemento 3.3.90.33 foi registrado na linha do Contrato nº 66/2024. | W14: =IF($E14="","",IF(COUNTIF($E$8:$E$107,$E14)>1,"DUPLICADO","OK")) -> OK
A15: 8 | C15: LOCAÇÃO NOVO IMOVEL SEDE SMD EM UNIÃO BANDEIRANTES. | H15: Locação do imóvel onde funciona a sede administrativa do Distrito de União Bandeirantes. | M15: 3000 | N15: 8 | O15: =IFERROR(M15*N15,0) -> 24000 | P15: =IFERROR(ROUNDDOWN(Q15/M15,0),0) -> 0 | R15: =IFERROR(O15-Q15,0) -> 24000 | S15: =IFERROR(Q15/O15,0) -> 0 | U15: =IFERROR(R15-T15,0) -> 24000 | V15: Previsão para locação de novo imóvel destinado à sede administrativa do Distrito de União Bandeirantes, em substituição ao imóvel atualmente utilizado, cuja estrutura não oferece condições adequadas para o atendimento à população, o desenvolvimento das atividades administrativas e a guarda dos equipamentos da SMD. Prevê-se a prorrogação temporária da locação atual, de outubro de 2026 até abril de 2027, para assegurar a continuidade do atendimento, com início da instrução do novo processo em janeiro de 2027. A seleção observará a adequação do imóvel, a avaliação mercadológica, a regularidade documental e a busca pelo menor valor compatível com as necessidades da unidade, em atenção à economicidade e ao interesse público. | W15: =IF($E15="","",IF(COUNTIF($E$8:$E$107,$E15)>1,"DUPLICADO","OK"))
A16: 9 | O16: =IFERROR(M16*N16,0) -> 0 | P16: =IFERROR(ROUNDDOWN(Q16/M16,0),0) -> 0 | R16: =IFERROR(O16-Q16,0) -> 0 | S16: =IFERROR(Q16/O16,0) -> 0 | U16: =IFERROR(R16-T16,0) -> 0 | W16: =IF($E16="","",IF(COUNTIF($E$8:$E$107,$E16)>1,"DUPLICADO","OK"))
A17: 10 | O17: =IFERROR(M17*N17,0) -> 0 | P17: =IFERROR(ROUNDDOWN(Q17/M17,0),0) -> 0 | R17: =IFERROR(O17-Q17,0) -> 0 | S17: =IFERROR(Q17/O17,0) -> 0 | U17: =IFERROR(R17-T17,0) -> 0 | W17: =IF($E17="","",IF(COUNTIF($E$8:$E$107,$E17)>1,"DUPLICADO","OK"))
A18: 11 | O18: =IFERROR(M18*N18,0) -> 0 | P18: =IFERROR(ROUNDDOWN(Q18/M18,0),0) -> 0 | R18: =IFERROR(O18-Q18,0) -> 0 | S18: =IFERROR(Q18/O18,0) -> 0 | U18: =IFERROR(R18-T18,0) -> 0 | W18: =IF($E18="","",IF(COUNTIF($E$8:$E$107,$E18)>1,"DUPLICADO","OK"))
A19: 12 | O19: =IFERROR(M19*N19,0) -> 0 | P19: =IFERROR(ROUNDDOWN(Q19/M19,0),0) -> 0 | R19: =IFERROR(O19-Q19,0) -> 0 | S19: =IFERROR(Q19/O19,0) -> 0 | U19: =IFERROR(R19-T19,0) -> 0 | W19: =IF($E19="","",IF(COUNTIF($E$8:$E$107,$E19)>1,"DUPLICADO","OK"))
A20: 13 | O20: =IFERROR(M20*N20,0) -> 0 | P20: =IFERROR(ROUNDDOWN(Q20/M20,0),0) -> 0 | R20: =IFERROR(O20-Q20,0) -> 0 | S20: =IFERROR(Q20/O20,0) -> 0 | U20: =IFERROR(R20-T20,0) -> 0 | W20: =IF($E20="","",IF(COUNTIF($E$8:$E$107,$E20)>1,"DUPLICADO","OK"))
A21: 14 | O21: =IFERROR(M21*N21,0) -> 0 | P21: =IFERROR(ROUNDDOWN(Q21/M21,0),0) -> 0 | R21: =IFERROR(O21-Q21,0) -> 0 | S21: =IFERROR(Q21/O21,0) -> 0 | U21: =IFERROR(R21-T21,0) -> 0 | W21: =IF($E21="","",IF(COUNTIF($E$8:$E$107,$E21)>1,"DUPLICADO","OK"))
A22: 15 | O22: =IFERROR(M22*N22,0) -> 0 | P22: =IFERROR(ROUNDDOWN(Q22/M22,0),0) -> 0 | R22: =IFERROR(O22-Q22,0) -> 0 | S22: =IFERROR(Q22/O22,0) -> 0 | U22: =IFERROR(R22-T22,0) -> 0 | W22: =IF($E22="","",IF(COUNTIF($E$8:$E$107,$E22)>1,"DUPLICADO","OK"))
A23: 16 | O23: =IFERROR(M23*N23,0) -> 0 | P23: =IFERROR(ROUNDDOWN(Q23/M23,0),0) -> 0 | R23: =IFERROR(O23-Q23,0) -> 0 | S23: =IFERROR(Q23/O23,0) -> 0 | U23: =IFERROR(R23-T23,0) -> 0 | W23: =IF($E23="","",IF(COUNTIF($E$8:$E$107,$E23)>1,"DUPLICADO","OK"))
A24: 17 | O24: =IFERROR(M24*N24,0) -> 0 | P24: =IFERROR(ROUNDDOWN(Q24/M24,0),0) -> 0 | R24: =IFERROR(O24-Q24,0) -> 0 | S24: =IFERROR(Q24/O24,0) -> 0 | U24: =IFERROR(R24-T24,0) -> 0 | W24: =IF($E24="","",IF(COUNTIF($E$8:$E$107,$E24)>1,"DUPLICADO","OK"))
A25: 18 | O25: =IFERROR(M25*N25,0) -> 0 | P25: =IFERROR(ROUNDDOWN(Q25/M25,0),0) -> 0 | R25: =IFERROR(O25-Q25,0) -> 0 | S25: =IFERROR(Q25/O25,0) -> 0 | U25: =IFERROR(R25-T25,0) -> 0 | W25: =IF($E25="","",IF(COUNTIF($E$8:$E$107,$E25)>1,"DUPLICADO","OK"))
A26: 19 | O26: =IFERROR(M26*N26,0) -> 0 | P26: =IFERROR(ROUNDDOWN(Q26/M26,0),0) -> 0 | R26: =IFERROR(O26-Q26,0) -> 0 | S26: =IFERROR(Q26/O26,0) -> 0 | U26: =IFERROR(R26-T26,0) -> 0 | W26: =IF($E26="","",IF(COUNTIF($E$8:$E$107,$E26)>1,"DUPLICADO","OK"))
A27: 20 | O27: =IFERROR(M27*N27,0) -> 0 | P27: =IFERROR(ROUNDDOWN(Q27/M27,0),0) -> 0 | R27: =IFERROR(O27-Q27,0) -> 0 | S27: =IFERROR(Q27/O27,0) -> 0 | U27: =IFERROR(R27-T27,0) -> 0 | W27: =IF($E27="","",IF(COUNTIF($E$8:$E$107,$E27)>1,"DUPLICADO","OK"))
... A107: 100 | O107: =IFERROR(M107*N107,0) -> 0 | P107: =IFERROR(ROUNDDOWN(Q107/M107,0),0) -> 0 | R107: =IFERROR(O107-Q107,0) -> 0 | S107: =IFERROR(Q107/O107,0) -> 0 | U107: =IFERROR(R107-T107,0) -> 0 | W107: =IF($E107="","",IF(COUNTIF($E$8:$E$107,$E107)>1,"DUPLICADO","OK"))

Sheet Pretensões 2027
A1: UNIDADE: Superintendência Municipal de Distritos - SMD
A3: PLANEJAMENTO DE CONTRATAÇÕES — PRETENSÕES FUTURAS 2027
A5: TOTAL | F5: =SUM(F8:F107) -> 1409000
A7: Nº | B7: Objeto Pretendido | C7: Tipo de Objeto | D7: Quantidade Estimada | E7: Unidade de Medida | F7: Valor Estimado (R$) | G7: Trimestre Previsto para Contratação | H7: Grau de Prioridade | I7: Fonte de Recursos | J7: Justificativa da Necessidade | K7: Observações
A8: 1 | B8: Manutenção preventiva e corretiva da frota, com aquisição de peças, componentes, pneus e contratação dos serviços necessários | C8: Contrato de Prestação de Serviços Contínuos | D8: 1 | E8: Lote anual | F8: 175000 | G8: 1º Trimestre | H8: Alta | I8: Recursos Livres | J8: Assegurar a disponibilidade, a segurança e a continuidade operacional da frota utilizada no atendimento da sede e dos distritos, mediante manutenção preventiva e corretiva e fornecimento dos insumos necessários, reduzindo o risco de indisponibilidade dos veículos e de prejuízo às atividades administrativas e de campo. | K8: Planejamento anual consolidado no valor de R$ 175.000,00, abrangendo peças, componentes, pneus, materiais e serviços de manutenção. A modelagem da contratação, a eventual divisão em itens ou lotes, os quantitativos, as especificações e os preços de referência serão definidos no DFD e nos estudos técnicos, com base na identificação da frota, no histórico de manutenção e em pesquisa de preços.
A9: 2 | B9: Aquisição de água mineral para a sede e as 13 unidades distritais | C9: Contrato de Fornecimento Integral (Compras) | D9: 1 | E9: Lote anual | F9: 25000 | G9: 1º Trimestre | H9: Alta | I9: Recursos Livres | J9: Assegurar o fornecimento contínuo de água potável aos servidores e usuários da sede e das 13 unidades distritais durante o exercício. | K9: Estimativa anual sujeita ao detalhamento dos quantitativos no DFD, considerando o consumo projetado, o estoque disponível e os preços vigentes na data da contratação.
A10: 3 | B10: Aquisição de materiais de limpeza e higienização | C10: Contrato de Fornecimento Integral (Compras) | D10: 1 | E10: Lote anual | F10: 25000 | G10: 1º Trimestre | H10: Alta | I10: Recursos Livres | J10: Manter condições adequadas de limpeza, higienização, salubridade e conservação nos ambientes da sede e das 13 unidades distritais, prevenindo o desabastecimento de insumos necessários ao funcionamento regular das unidades. | K10: Estimativa anual para atendimento contínuo da sede e dos 13 distritos. Os quantitativos serão detalhados no DFD com base no consumo, no estoque e na pesquisa de preços. Papel higiênico, papel-toalha e guardanapos permanecem em item separado para evitar duplicidade.
A11: 4 | B11: Aquisição de copos descartáveis para água e café | C11: Contrato de Fornecimento Integral (Compras) | D11: 121 | E11: Caixas | F11: 15000 | G11: 1º Trimestre | H11: Alta | I11: Recursos Livres | J11: Atender ao consumo necessário para disponibilização de água e café na sede administrativa e nas 13 unidades distritais durante o exercício. | K11: Estimativa anual a ser detalhada no DFD, com definição dos tipos, capacidades e quantitativos conforme a demanda efetiva das unidades e a pesquisa de preços.
A12: 5 | B12: Aquisição de materiais de expediente para a sede e unidades distritais | C12: Contrato de Fornecimento Integral (Compras) | D12: 1 | E12: Lote anual | F12: 25000 | G12: 1º Trimestre | H12: Alta | I12: Recursos Livres | J12: Assegurar a continuidade da instrução processual, dos registros administrativos, do arquivamento e do atendimento realizado pela sede da SMD e pelas unidades distritais, evitando desabastecimento de insumos indispensáveis às rotinas de trabalho. | K12: Estimativa anual para atendimento da sede e dos 13 distritos. Os quantitativos e as especificações serão consolidados no DFD com base no consumo histórico, no estoque disponível e na pesquisa de preços, priorizando aquisição compatível com a demanda efetiva.
A13: 6 | B13: Aquisição de papel toalha, papel higiênico e guardanapos | C13: Contrato de Fornecimento Integral (Compras) | D13: 1560 | E13: Pacotes | F13: 20000 | G13: 1º Trimestre | H13: Alta | I13: Recursos Livres | J13: Assegurar o abastecimento contínuo de insumos de higiene e uso sanitário na sede e nas 13 unidades distritais, necessários à manutenção das condições de salubridade e ao atendimento regular de servidores e usuários. | K13: Estimativa anual para os 12 meses de 2027. Os quantitativos serão consolidados no DFD conforme consumo histórico, estoque disponível e pesquisa de preços, mantendo-se este objeto separado dos demais materiais de limpeza para controle e prevenção de duplicidade.
A14: 7 | B14: Aquisição de café, açúcar e recarga de gás de cozinha | C14: Contrato de Fornecimento Integral (Compras) | D14: 1 | E14: Lote anual | F14: 20000 | G14: 1º Trimestre | H14: Alta | I14: Recursos Livres | J14: Atender à rotina de copa da sede administrativa e das unidades distritais durante o exercício, com fornecimento regular dos insumos de consumo previstos. | K14: Estimativa anual para os 12 meses de 2027. Os quantitativos serão definidos no DFD conforme consumo projetado, estoque disponível e pesquisa de preços.
A15: 8 | B15: Diárias civis para deslocamentos institucionais e operacionais | D15: 1 | E15: Estimativa anual | F15: 120000 | G15: 1º Trimestre | H15: Alta | I15: Recursos Livres | J15: Custear deslocamentos de servidores para atendimento das atividades da sede, dos distritos e de localidades do Município. | K15: Previsão anual definida pela SMD. Despesa orçamentária não contratual, mantida nesta aba para demonstrar a necessidade integral de 2027.
A16: 9 | B16: Diárias indenizatórias para deslocamentos no território municipal | D16: 1 | E16: Estimativa anual | F16: 70000 | G16: 1º Trimestre | H16: Alta | I16: Recursos Livres | J16: Custear as indenizações de deslocamento necessárias às atividades de campo e ao atendimento dos distritos. | K16: Previsão anual definida pela SMD. Despesa orçamentária não contratual, mantida nesta aba para demonstrar a necessidade integral de 2027.
A17: 10 | B17: Suprimento de fundos para despesas com materiais de consumo e serviços de terceiros na sede e nos 13 distritos | D17: 1 | E17: Estimativa anual | F17: 140000 | G17: 1º Trimestre | H17: Alta | I17: Recursos Livres | J17: Viabilizar o atendimento de despesas excepcionais, urgentes, de pequeno vulto e de pronto pagamento, nas hipóteses admitidas pela regulamentação aplicável, abrangendo a aquisição de materiais de consumo e a contratação de serviços de terceiros necessários ao funcionamento da sede e das unidades distritais. | K17: Previsão anual unificada no valor de R$ 140.000,00, reunindo as necessidades anteriormente apresentadas em itens distintos para material de consumo e serviços de terceiros, sem duplicidade de recursos. A unificação possui finalidade de planejamento; na execução orçamentária, as despesas deverão ser classificadas, empenhadas e prestadas contas nos elementos correspondentes à sua natureza e de acordo com cada concessão.
A18: 11 | B18: Aquisição de cartuchos de toner para as impressoras da SMD | C18: Contrato de Fornecimento Integral (Compras) | D18: 50 | E18: Unidades | F18: 20000 | G18: 1º Trimestre | H18: Alta | I18: Recursos Livres | J18: Assegurar a continuidade da impressão de documentos necessários à instrução processual, às comunicações administrativas e ao atendimento das unidades que utilizam equipamentos próprios. | K18: Estimativa preliminar para atendimento durante os 12 meses de 2027. Os modelos, os quantitativos e a compatibilidade dos cartuchos serão definidos após o inventário das impressoras, a verificação do estoque e a consolidação do DFD, com posterior pesquisa de preços.
A19: 12 | B19: Aquisição de equipamentos de informática para a sede e unidades distritais | C19: Contrato de Fornecimento Integral (Compras) | D19: 1 | E19: Lote | F19: 50000 | G19: 2º Trimestre | H19: Alta | I19: Recursos Livres | J19: Substituir equipamentos defasados e estruturar os postos de trabalho da sede e dos distritos. | K19: Previsão inicial para aquisição gradual dos equipamentos de informática mais urgentes. O levantamento preliminar era superior, mas a dotação foi reduzida para reforçar os contratos continuados anualizados.
A20: 13 | B20: Aquisição de roçadeiras profissionais, motopodas telescópicas e kits de ferramentas | C20: Contrato de Fornecimento Integral (Compras) | D20: 40 | E20: Equipamentos e kits | F20: 80000 | G20: 1º Trimestre | H20: Alta | I20: Recursos Livres | J20: Atender os serviços de roçagem, poda e manutenção das áreas públicas nos 13 distritos. | K20: Previsão anual reforçada para aquisição de roçadeiras profissionais, motopodas telescópicas e kits de ferramentas destinados às atividades operacionais nos distritos. Os quantitativos e as especificações definitivas dependerão do levantamento técnico e da pesquisa de preços.
A21: 14 | B21: Aquisição de acessórios, peças e lubrificantes para roçadeiras e motopodas | C21: Contrato de Fornecimento Integral (Compras) | D21: 1 | E21: Lote anual | F21: 25000 | G21: 1º Trimestre | H21: Alta | I21: Recursos Livres | J21: Garantir o funcionamento e a manutenção dos equipamentos durante os 12 meses do exercício. | K21: Estimativa anual para acessórios, peças e lubrificantes necessários ao funcionamento das roçadeiras e motopodas. A relação definitiva será ajustada aos modelos dos equipamentos adquiridos.
A22: 15 | B22: Aquisição de equipamentos de proteção individual para operadores de roçadeiras e motopodas | C22: Contrato de Fornecimento Integral (Compras) | D22: 15 | E22: Kits | F22: 25000 | G22: 1º Trimestre | H22: Alta | I22: Recursos Livres | J22: Proteger os operadores durante os serviços de roçagem e poda nos distritos. | K22: Estimativa anual para equipamentos de proteção individual dos operadores. O valor foi dimensionado dentro da proposta global e será revisto após a definição das especificações e dos preços unitários.
A23: 16 | B23: Contratação de serviço de agenciamento de passagens aéreas | C23: Contrato de Prestação de Serviços Contínuos | D23: 20 | E23: Viagens completas | F23: 40000 | G23: 1º Trimestre | H23: Média | I23: Recursos Livres | J23: Atender viagens institucionais para capacitação, aperfeiçoamento e representação da SMD. | K23: Estimativa anual priorizada para agenciamento de passagens. O quantitativo será compatibilizado com o valor disponível, sem incluir diárias ou deslocamentos terrestres.
A24: 17 | B24: Reforma da sede administrativa do Distrito de Abunã | C24: Contrato de Serviços de Engenharia | D24: 1 | E24: Prédio | F24: 50000 | G24: 1º Trimestre | H24: Alta | I24: Recursos Livres | J24: Recuperar as condições de segurança, conservação e funcionamento da sede administrativa do Distrito de Abunã, mediante avaliação das necessidades de execução de muro, adequação do padrão e do poste de energia elétrica e serviços de pintura. As intervenções são necessárias à preservação do imóvel público e à continuidade do atendimento administrativo à população. | K24: Estimativa preliminar extraída do Relatório de Necessidade de Reparos de Sedes Próprias, sujeita à vistoria e ao estudo de viabilidade por equipe técnica de engenharia. A definição do escopo, dos quantitativos, das soluções construtivas, do cronograma e do orçamento de referência deverá preceder a contratação, com pesquisa de preços e seleção da alternativa tecnicamente adequada e economicamente mais vantajosa para a Administração.
A25: 18 | B25: Reforma e avaliação da adequação da sede administrativa do Distrito de Calama | C25: Contrato de Serviços de Engenharia | D25: 1 | E25: Prédio | F25: 200000 | G25: 1º Trimestre | H25: Alta | I25: Recursos Livres | J25: Restabelecer condições adequadas de uso da sede administrativa do Distrito de Calama, considerando a necessidade indicada de reparos nas instalações hidráulicas, recuperação do telhado e avaliação técnica da solução para ampliação, substituição ou construção de estrutura compatível com as atividades da unidade. A medida busca assegurar segurança, salubridade e continuidade dos serviços públicos no distrito. | K25: Estimativa preliminar extraída do Relatório de Necessidade de Reparos de Sedes Próprias, sujeita à vistoria e ao estudo de viabilidade por equipe técnica de engenharia. A definição do escopo, dos quantitativos, das soluções construtivas, do cronograma e do orçamento de referência deverá preceder a contratação, com pesquisa de preços e seleção da alternativa tecnicamente adequada e economicamente mais vantajosa para a Administração.
A26: 19 | B26: Reforma da sede administrativa do Distrito de Demarcação | C26: Contrato de Serviços de Engenharia | D26: 1 | E26: Prédio | F26: 15000 | G26: 1º Trimestre | H26: Alta | I26: Recursos Livres | J26: Adequar as condições de abastecimento de água e conservação da sede administrativa do Distrito de Demarcação, mediante avaliação para instalação de reservatório de água com capacidade estimada de 1.000 litros e execução de pintura, de modo a garantir condições mínimas de funcionamento e atendimento à população. | K26: Estimativa preliminar extraída do Relatório de Necessidade de Reparos de Sedes Próprias, sujeita à vistoria e ao estudo de viabilidade por equipe técnica de engenharia. A definição do escopo, dos quantitativos, das soluções construtivas, do cronograma e do orçamento de referência deverá preceder a contratação, com pesquisa de preços e seleção da alternativa tecnicamente adequada e economicamente mais vantajosa para a Administração.
A27: 20 | B27: Adequação das instalações elétricas da sede administrativa do Distrito de Fortaleza do Abunã | C27: Contrato de Serviços de Engenharia | D27: 1 | E27: Prédio | F27: 20000 | G27: 1º Trimestre | H27: Alta | I27: Recursos Livres | J27: Corrigir e adequar as instalações elétricas da sede administrativa do Distrito de Fortaleza do Abunã, reduzindo riscos à segurança de servidores, usuários, equipamentos e ao patrimônio público e assegurando condições regulares para a continuidade das atividades administrativas. | K27: Estimativa preliminar extraída do Relatório de Necessidade de Reparos de Sedes Próprias, sujeita à vistoria e ao estudo de viabilidade por equipe técnica de engenharia. A definição do escopo, dos quantitativos, das soluções construtivas, do cronograma e do orçamento de referência deverá preceder a contratação, com pesquisa de preços e seleção da alternativa tecnicamente adequada e economicamente mais vantajosa para a Administração.
A28: 21 | B28: Complementação da reforma da sede administrativa do Distrito de Jaci-Paraná | C28: Contrato de Serviços de Engenharia | D28: 1 | E28: Prédio | F28: 20000 | G28: 1º Trimestre | H28: Alta | I28: Recursos Livres | J28: Prever recursos para serviços complementares necessários à conclusão ou adequação da reforma em andamento na sede administrativa do Distrito de Jaci-Paraná, conforme apuração técnica do estágio da obra e das intervenções remanescentes, com o objetivo de restabelecer plenamente as condições de uso do imóvel. | K28: Estimativa preliminar extraída do Relatório de Necessidade de Reparos de Sedes Próprias, sujeita à vistoria e ao estudo de viabilidade por equipe técnica de engenharia. A definição do escopo, dos quantitativos, das soluções construtivas, do cronograma e do orçamento de referência deverá preceder a contratação, com pesquisa de preços e seleção da alternativa tecnicamente adequada e economicamente mais vantajosa para a Administração.
A29: 22 | B29: Reforma do pátio da sede administrativa do Distrito de Nova Califórnia | C29: Contrato de Serviços de Engenharia | D29: 1 | E29: Prédio | F29: 80000 | G29: 1º Trimestre | H29: Alta | I29: Recursos Livres | J29: Recuperar e adequar o pátio da sede administrativa do Distrito de Nova Califórnia, garantindo melhores condições de acesso, circulação, segurança e conservação do imóvel utilizado na prestação dos serviços públicos distritais. | K29: Estimativa preliminar extraída do Relatório de Necessidade de Reparos de Sedes Próprias, sujeita à vistoria e ao estudo de viabilidade por equipe técnica de engenharia. A definição do escopo, dos quantitativos, das soluções construtivas, do cronograma e do orçamento de referência deverá preceder a contratação, com pesquisa de preços e seleção da alternativa tecnicamente adequada e economicamente mais vantajosa para a Administração.
... A33: 26 | B33: Locação de imóvel para implantação da sede administrativa do Distrito de Rio Pardo | C33: Contrato de Locação de Imóveis | D33: 12 | E33: Mês | F33: 24000 | G33: 1º Trimestre | H33: Alta | I33: Recursos Livres | J33: Implantar estrutura física adequada para o funcionamento da administração distrital de Rio Pardo, que atualmente não dispõe de sede própria, assegurando local apropriado para o atendimento à população, o desenvolvimento das rotinas administrativas e a continuidade dos serviços públicos no distrito. | K33: Estimativa preliminar de até R$ 2.000,00 mensais, totalizando R$ 24.000,00 para 12 meses. A locação dependerá de estudo de viabilidade, definição das necessidades da unidade, pesquisa de mercado, avaliação do imóvel, regularidade documental e demonstração de compatibilidade do preço, buscando-se o menor valor possível entre as alternativas que atendam ao interesse público e aos requisitos técnicos.
A34: 27
A35: 28
A36: 29
A37: 30
A38: 31
A39: 32
A40: 33
A41: 34
A42: 35
A43: 36
A44: 37
A45: 38
... A107: 100

Sheet Base de Dados
A1: BASE DE DADOS — DESDOBRAMENTO INDIVIDUALIZADO POR CONTRATO | L1: =TRIM(MID('2027'!$A$1,FIND(":",'2027'!$A$1)+2,200)) -> Superintendência Municipal de Distritos - SMD
A2: 1. CADASTRO DO CONTRATO | AC2: 2. GESTÃO FINANCEIRA | AT2: 3. CONTROLE DA EXECUÇÃO | BA2: 4. ALTERAÇÕES CONTRATUAIS | BG2: 5. ALERTAS AUTOMÁTICOS | BN2: 6. PAGO POR FONTE DE RECURSO
A3: Nº do Contrato/Ano | B3: Ficha (nome da aba) | C3: Nº do Processo SEI | D3: Contratada (Nome/Razão Social) | E3: CPF/CNPJ da Contratada | F3: Nº do Contrato/Ano | G3: Tipo de Objeto | H3: Objeto do Contrato | J3: Regime de Execução | K3: Código da Ação | L3: Tipo de Empenho | M3: Início da Vigência | N3: Término da Vigência | O3: Unidade Gestora | Q3: Programa | R3: Natureza da Despesa | S3: Elemento de Despesa | T3: Fonte de Recurso | U3: Categoria Econômica | V3: Modalidade de Licitação | X3: Fiscal do Contrato | Y3: Gestor do Contrato | Z3: Valor Original do Contrato | AA3: Data de Assinatura | AB3: Situação | AC3: Exercício Financeiro | AD3: Valor Mensal do Contrato | AE3: Meses Vigentes no Exercício | AF3: Valor Total no Exercício | AG3: Dotação Inicial | AH3: Dotação Atualizada | AI3: Valor Empenhado no Exercício | AJ3: Valor Liquidado | AK3: Valor Pago | AL3: Saldo a Empenhar | AM3: Saldo a Liquidar | AN3: Saldo a Pagar | AO3: % Empenhado no Exercício | AP3: % Executado (Pago/Total) | AQ3: Restos a Pagar | AR3: Saldo Orçamentário da Unidade | AS3: Valor a Suplementar | AT3: Valor Executado no Mês | AV3: % Físico Executado | AW3: Última Medição | AX3: Próxima Medição | AY3: Último Pagamento | AZ3: Próximo Pagamento Previsto | BA3: Qtde de Aditivos | BB3: Valor Acrescido (Aditivos) | BC3: Valor Suprimido (Aditivos) | BD3: Novo Valor do Contrato | BE3: Nova Vigência (após aditivo) | BF3: Última Justificativa | BG3: Dias para Vencer | BH3: Vence em até 90 dias | BI3: Contrato Vencido | BJ3: Saldo a Empenhar < 20% | BK3: Execução acima de 90% | BL3: Sem pagamento há +60 dias | BM3: Observações | BN3: Pago — Recurso Livre | BO3: Pago — Recurso Vinculado | BP3: Pago — Convênio | BQ3: Pago — Operação de Crédito | BR3: Pago — Emendas Parlamentares | BS3: Verificação — Pago vs. Fonte
A4: =IF('2027'!$E$8="","",'2027'!$E$8) -> 66/2024 | B4: C01 | C4: =IF('2027'!$B$8="","",'2027'!$B$8) -> 024.000147/2025-98 | D4: =IF('2027'!$C$8="","",'2027'!$C$8) -> RECHE GALDEANO & CIA LTDA | E4: =IF('2027'!$D$8="","",'2027'!$D$8) -> 08.713.403/0001-90 | F4: =IF('2027'!$E$8="","",'2027'!$E$8) -> 66/2024 | G4: =IF('2027'!$F$8="","",'2027'!$F$8) -> Contrato de Prestação de Serviços Contínuos | H4: =IF('2027'!$H$8="","",'2027'!$H$8) -> Locação de 11 veículos utilitários leves, sem condutor, para atendimento da sede e dos distritos. | J4: =IF('2027'!$I$8="","",'2027'!$I$8) -> Contrato continuado | K4: =IF($B4="","",IFERROR(IF(INDIRECT("'"&$B4&"'!$B$10")="","",INDIRECT("'"&$B4&"'!$B$10")),"")) | L4: =IF('2027'!$J$8="","",'2027'!$J$8) -> Global | M4: =IF('2027'!$K$8="","",'2027'!$K$8) -> 9/26/2024 | N4: =IF('2027'!$L$8="","",'2027'!$L$8) -> 9/26/2027 | O4: =IF($B4="","","SMD") -> SMD | Q4: =IF($B4="","",IFERROR(IF(INDIRECT("'"&$B4&"'!$B$11")="","",INDIRECT("'"&$B4&"'!$B$11")),"")) | R4: =IF($B4="","",IFERROR(IF(INDIRECT("'"&$B4&"'!$F$11")="","",INDIRECT("'"&$B4&"'!$F$11")),"")) | S4: =IF($B4="","",IFERROR(IF(INDIRECT("'"&$B4&"'!$J$11")="","",INDIRECT("'"&$B4&"'!$J$11")),"")) | T4: =IF($B4="","",IFERROR(IF(INDIRECT("'"&$B4&"'!$J$10")="","",INDIRECT("'"&$B4&"'!$J$10")),"")) | U4: =IF($B4="","",IFERROR(IF(INDIRECT("'"&$B4&"'!$F$10")="","",INDIRECT("'"&$B4&"'!$F$10")),"")) | V4: =IF('2027'!$G$8="","",'2027'!$G$8) -> Carona (ARP Externa) | X4: =IF($B4="","",IFERROR(IF(INDIRECT("'"&$B4&"'!$F$12")="","",INDIRECT("'"&$B4&"'!$F$12")),"")) | Y4: =IF($B4="","",IFERROR(IF(INDIRECT("'"&$B4&"'!$B$12")="","",INDIRECT("'"&$B4&"'!$B$12")),"")) | Z4: =IF($B4="","",IFERROR(IF(INDIRECT("'"&$B4&"'!$J$13")="","",INDIRECT("'"&$B4&"'!$J$13")),"")) | AB4: =IF($B4="","",IFERROR(IF(INDIRECT("'"&$B4&"'!$J$4")="","",INDIRECT("'"&$B4&"'!$J$4")),"")) | AC4: =IF($B4="","",2026) -> 2026 | AD4: =IF('2027'!$M$8="","",'2027'!$M$8) -> 42393.45 | AE4: =IF('2027'!$N$8="","",'2027'!$N$8) -> 12 | AF4: =IF('2027'!$O$8="","",'2027'!$O$8) -> 508721.4 | AI4: =IF('2027'!$Q$8="","",'2027'!$Q$8) -> 508721.4 | AJ4: =IF($B4="","",IFERROR(IF(INDIRECT("'"&$B4&"'!$D$21")="","",INDIRECT("'"&$B4&"'!$D$21")),"")) -> 0 | AK4: =IF($B4="","",IFERROR(IF(INDIRECT("'"&$B4&"'!$E$21")="","",INDIRECT("'"&$B4&"'!$E$21")),"")) -> 0 | AL4: =IF('2027'!$R$8="","",'2027'!$R$8) -> 0 | AM4: =IFERROR(AI4-AJ4,0) -> 508721.4 | AN4: =IFERROR(AJ4-AK4,0) -> 0 | AO4: =IF('2027'!$S$8="","",'2027'!$S$8) -> 1 | AP4: =IFERROR(AK4/AF4,0) -> 0 | AQ4: =IF($B4="","",IFERROR(IF(INDIRECT("'"&$B4&"'!$K$21")="","",INDIRECT("'"&$B4&"'!$K$21")),"")) -> 0 | AR4: =IF('2027'!$T$8="","",'2027'!$T$8) -> 19.3 | AS4: =IF('2027'!$U$8="","",'2027'!$U$8) -> -19.3 | AT4: =IF($B4="","",IFERROR(IF(INDIRECT("'"&$B4&"'!$B$15")="","",INDIRECT("'"&$B4&"'!$B$15")),"")) -> 0 | AV4: =IF($B4="","",IFERROR(IF(INDIRECT("'"&$B4&"'!$B$14")="","",INDIRECT("'"&$B4&"'!$B$14")),"")) | AW4: =IF($B4="","",AY4) | AX4: =IF($B4="","",IFERROR(IF(INDIRECT("'"&$B4&"'!$F$14")="","",INDIRECT("'"&$B4&"'!$F$14")),"")) | AY4: =IF($B4="","",IFERROR(IF(INDIRECT("'"&$B4&"'!$D$35")="","",INDIRECT("'"&$B4&"'!$D$35")),"")) | AZ4: =IF($B4="","",IFERROR(IF(INDIRECT("'"&$B4&"'!$J$14")="","",INDIRECT("'"&$B4&"'!$J$14")),"")) | BA4: =IF($B4="","",IFERROR(IF(INDIRECT("'"&$B4&"'!$I$21")="","",INDIRECT("'"&$B4&"'!$I$21")),"")) -> 0 | BB4: =IF($B4="","",IFERROR(IF(INDIRECT("'"&$B4&"'!$C$67")="","",INDIRECT("'"&$B4&"'!$C$67")),"")) -> 0 | BC4: =IF($B4="","",IFERROR(IF(INDIRECT("'"&$B4&"'!$D$68")="","",INDIRECT("'"&$B4&"'!$D$68")),"")) -> 0 | BD4: =IFERROR(Z4+BB4-BC4,0) -> 0 | BE4: =IF($B4="","",IFERROR(IF(INDIRECT("'"&$B4&"'!$J$21")="","",INDIRECT("'"&$B4&"'!$J$21")),"")) | BF4: =IF($B4="","",IFERROR(IF(INDIRECT("'"&$B4&"'!$F$15")="","",INDIRECT("'"&$B4&"'!$F$15")),"")) | BG4: =IFERROR(N4-TODAY(),"") | BH4: =IF(N4="","",IF(AND(N4-TODAY()>=0,N4-TODAY()<=90),"Sim","Não")) -> #VALUE! | BI4: =IF(N4="","",IF(N4<TODAY(),"Sim","Não")) -> Não | BJ4: =IF(AF4=0,"",IF(IFERROR(AL4/AF4,0)<0.2,"Sim","Não")) -> Sim | BK4: =IF(AF4=0,"",IF(IFERROR(AK4/AF4,0)>0.9,"Sim","Não")) -> Não | BL4: =IF(AY4="","",IF(TODAY()-AY4>60,"Sim","Não")) | BM4: =IF('2027'!$V$8="","",'2027'!$V$8) -> Projeção anual para 2027. Referência de 2026: R$ 508.721,40 empenhados. O saldo de R$ 19,30 do elemento 3.3.90.33, compartilhado com o Contrato nº 64/2025, foi registrado somente nesta linha para evitar duplicidade. | BN4: =IF($B4="","",IFERROR(IF(INDIRECT("'"&$B4&"'!$B$24")="","",INDIRECT("'"&$B4&"'!$B$24")),"")) -> 0 | BO4: =IF($B4="","",IFERROR(IF(INDIRECT("'"&$B4&"'!$B$25")="","",INDIRECT("'"&$B4&"'!$B$25")),"")) -> 0 | BP4: =IF($B4="","",IFERROR(IF(INDIRECT("'"&$B4&"'!$B$26")="","",INDIRECT("'"&$B4&"'!$B$26")),"")) -> 0 | BQ4: =IF($B4="","",IFERROR(IF(INDIRECT("'"&$B4&"'!$B$27")="","",INDIRECT("'"&$B4&"'!$B$27")),"")) -> 0 | BR4: =IF($B4="","",IFERROR(IF(INDIRECT("'"&$B4&"'!$B$28")="","",INDIRECT("'"&$B4&"'!$B$28")),"")) -> 0 | BS4: =IF($B4="","",IF(AK4="","",IF(ROUND(AK4-SUM(BN4:BR4),2)>0,"Verificar — pagamento sem fonte",IF(ROUND(AK4-SUM(BN4:BR4),2)<0,"Verificar — fonte > pago","OK")))) -> OK
A5: =IF('2027'!$E$9="","",'2027'!$E$9) -> 39/2022 | C5: =IF('2027'!$B$9="","",'2027'!$B$9) -> 024.000144/2025-54 | D5: =IF('2027'!$C$9="","",'2027'!$C$9) -> ISAIAS RODRIGUES DOS ANJOS | E5: =IF('2027'!$D$9="","",'2027'!$D$9) -> 768.916.742-04 | F5: =IF('2027'!$E$9="","",'2027'!$E$9) -> 39/2022 | G5: =IF('2027'!$F$9="","",'2027'!$F$9) -> Contrato de Locação de Imóveis | H5: =IF('2027'!$H$9="","",'2027'!$H$9) -> Locação do imóvel onde funciona a sede administrativa do Distrito de Extrema. | J5: =IF('2027'!$I$9="","",'2027'!$I$9) -> Contrato continuado | K5: =IF($B5="","",IFERROR(IF(INDIRECT("'"&$B5&"'!$B$10")="","",INDIRECT("'"&$B5&"'!$B$10")),"")) | L5: =IF('2027'!$J$9="","",'2027'!$J$9) -> Global | M5: =IF('2027'!$K$9="","",'2027'!$K$9) -> 7/23/2022 | N5: =IF('2027'!$L$9="","",'2027'!$L$9) -> 7/22/2027 | O5: =IF($B5="","","SMD") | Q5: =IF($B5="","",IFERROR(IF(INDIRECT("'"&$B5&"'!$B$11")="","",INDIRECT("'"&$B5&"'!$B$11")),"")) | R5: =IF($B5="","",IFERROR(IF(INDIRECT("'"&$B5&"'!$F$11")="","",INDIRECT("'"&$B5&"'!$F$11")),"")) | S5: =IF($B5="","",IFERROR(IF(INDIRECT("'"&$B5&"'!$J$11")="","",INDIRECT("'"&$B5&"'!$J$11")),"")) | T5: =IF($B5="","",IFERROR(IF(INDIRECT("'"&$B5&"'!$J$10")="","",INDIRECT("'"&$B5&"'!$J$10")),"")) | U5: =IF($B5="","",IFERROR(IF(INDIRECT("'"&$B5&"'!$F$10")="","",INDIRECT("'"&$B5&"'!$F$10")),"")) | V5: =IF('2027'!$G$9="","",'2027'!$G$9) -> Dispensa | X5: =IF($B5="","",IFERROR(IF(INDIRECT("'"&$B5&"'!$F$12")="","",INDIRECT("'"&$B5&"'!$F$12")),"")) | Y5: =IF($B5="","",IFERROR(IF(INDIRECT("'"&$B5&"'!$B$12")="","",INDIRECT("'"&$B5&"'!$B$12")),"")) | Z5: =IF($B5="","",IFERROR(IF(INDIRECT("'"&$B5&"'!$J$13")="","",INDIRECT("'"&$B5&"'!$J$13")),"")) | AB5: =IF($B5="","",IFERROR(IF(INDIRECT("'"&$B5&"'!$J$4")="","",INDIRECT("'"&$B5&"'!$J$4")),"")) | AC5: =IF($B5="","",2026) | AD5: =IF('2027'!$M$9="","",'2027'!$M$9) -> 4117 | AE5: =IF('2027'!$N$9="","",'2027'!$N$9) -> 12 | AF5: =IF('2027'!$O$9="","",'2027'!$O$9) -> 49404 | AI5: =IF('2027'!$Q$9="","",'2027'!$Q$9) -> 49721 | AJ5: =IF($B5="","",IFERROR(IF(INDIRECT("'"&$B5&"'!$D$21")="","",INDIRECT("'"&$B5&"'!$D$21")),"")) | AK5: =IF($B5="","",IFERROR(IF(INDIRECT("'"&$B5&"'!$E$21")="","",INDIRECT("'"&$B5&"'!$E$21")),"")) | AL5: =IF('2027'!$R$9="","",'2027'!$R$9) -> -317 | AM5: =IFERROR(AI5-AJ5,0) -> 49721 | AN5: =IFERROR(AJ5-AK5,0) -> 0 | AO5: =IF('2027'!$S$9="","",'2027'!$S$9) -> 1.0064165 | AP5: =IFERROR(AK5/AF5,0) -> 0 | AQ5: =IF($B5="","",IFERROR(IF(INDIRECT("'"&$B5&"'!$K$21")="","",INDIRECT("'"&$B5&"'!$K$21")),"")) | AR5: =IF('2027'!$T$9="","",'2027'!$T$9) -> 1959.02 | AS5: =IF('2027'!$U$9="","",'2027'!$U$9) -> -2276.02 | AT5: =IF($B5="","",IFERROR(IF(INDIRECT("'"&$B5&"'!$B$15")="","",INDIRECT("'"&$B5&"'!$B$15")),"")) | AV5: =IF($B5="","",IFERROR(IF(INDIRECT("'"&$B5&"'!$B$14")="","",INDIRECT("'"&$B5&"'!$B$14")),"")) | AW5: =IF($B5="","",AY5) | AX5: =IF($B5="","",IFERROR(IF(INDIRECT("'"&$B5&"'!$F$14")="","",INDIRECT("'"&$B5&"'!$F$14")),"")) | AY5: =IF($B5="","",IFERROR(IF(INDIRECT("'"&$B5&"'!$D$35")="","",INDIRECT("'"&$B5&"'!$D$35")),"")) | AZ5: =IF($B5="","",IFERROR(IF(INDIRECT("'"&$B5&"'!$J$14")="","",INDIRECT("'"&$B5&"'!$J$14")),"")) | BA5: =IF($B5="","",IFERROR(IF(INDIRECT("'"&$B5&"'!$I$21")="","",INDIRECT("'"&$B5&"'!$I$21")),"")) | BB5: =IF($B5="","",IFERROR(IF(INDIRECT("'"&$B5&"'!$C$67")="","",INDIRECT("'"&$B5&"'!$C$67")),"")) | BC5: =IF($B5="","",IFERROR(IF(INDIRECT("'"&$B5&"'!$D$68")="","",INDIRECT("'"&$B5&"'!$D$68")),"")) | BD5: =IFERROR(Z5+BB5-BC5,0) -> 0 | BE5: =IF($B5="","",IFERROR(IF(INDIRECT("'"&$B5&"'!$J$21")="","",INDIRECT("'"&$B5&"'!$J$21")),"")) | BF5: =IF($B5="","",IFERROR(IF(INDIRECT("'"&$B5&"'!$F$15")="","",INDIRECT("'"&$B5&"'!$F$15")),"")) | BG5: =IFERROR(N5-TODAY(),"") | BH5: =IF(N5="","",IF(AND(N5-TODAY()>=0,N5-TODAY()<=90),"Sim","Não")) -> #VALUE! | BI5: =IF(N5="","",IF(N5<TODAY(),"Sim","Não")) -> Não | BJ5: =IF(AF5=0,"",IF(IFERROR(AL5/AF5,0)<0.2,"Sim","Não")) -> Sim | BK5: =IF(AF5=0,"",IF(IFERROR(AK5/AF5,0)>0.9,"Sim","Não")) -> Não | BL5: =IF(AY5="","",IF(TODAY()-AY5>60,"Sim","Não")) | BM5: =IF('2027'!$V$9="","",'2027'!$V$9) -> Projeção anual para 2027. Referência de 2026: R$ 49.721,00 empenhados, considerando o processo principal e o processo apartado nº 024.000319/2026-12. O saldo de R$ 1.959,02 do elemento 3.3.90.36, compartilhado com as demais locações de pessoa física, foi registrado somente nesta linha. | BN5: =IF($B5="","",IFERROR(IF(INDIRECT("'"&$B5&"'!$B$24")="","",INDIRECT("'"&$B5&"'!$B$24")),"")) | BO5: =IF($B5="","",IFERROR(IF(INDIRECT("'"&$B5&"'!$B$25")="","",INDIRECT("'"&$B5&"'!$B$25")),"")) | BP5: =IF($B5="","",IFERROR(IF(INDIRECT("'"&$B5&"'!$B$26")="","",INDIRECT("'"&$B5&"'!$B$26")),"")) | BQ5: =IF($B5="","",IFERROR(IF(INDIRECT("'"&$B5&"'!$B$27")="","",INDIRECT("'"&$B5&"'!$B$27")),"")) | BR5: =IF($B5="","",IFERROR(IF(INDIRECT("'"&$B5&"'!$B$28")="","",INDIRECT("'"&$B5&"'!$B$28")),"")) | BS5: =IF($B5="","",IF(AK5="","",IF(ROUND(AK5-SUM(BN5:BR5),2)>0,"Verificar — pagamento sem fonte",IF(ROUND(AK5-SUM(BN5:BR5),2)<0,"Verificar — fonte > pago","OK"))))
A6: =IF('2027'!$E$10="","",'2027'!$E$10) -> 20/2023 | C6: =IF('2027'!$B$10="","",'2027'!$B$10) -> 024.000200/2025-51 | D6: =IF('2027'!$C$10="","",'2027'!$C$10) -> HELENA VASCONCELOS DE ALENCAR | E6: =IF('2027'!$D$10="","",'2027'!$D$10) -> 161.816.892-49 | F6: =IF('2027'!$E$10="","",'2027'!$E$10) -> 20/2023 | G6: =IF('2027'!$F$10="","",'2027'!$F$10) -> Contrato de Locação de Imóveis | H6: =IF('2027'!$H$10="","",'2027'!$H$10) -> Locação do imóvel onde funciona a sede administrativa do Distrito de Nazaré. | J6: =IF('2027'!$I$10="","",'2027'!$I$10) -> Contrato continuado | K6: =IF($B6="","",IFERROR(IF(INDIRECT("'"&$B6&"'!$B$10")="","",INDIRECT("'"&$B6&"'!$B$10")),"")) | L6: =IF('2027'!$J$10="","",'2027'!$J$10) -> Global | M6: =IF('2027'!$K$10="","",'2027'!$K$10) -> 4/14/2023 | N6: =IF('2027'!$L$10="","",'2027'!$L$10) -> 4/13/2027 | O6: =IF($B6="","","SMD") | Q6: =IF($B6="","",IFERROR(IF(INDIRECT("'"&$B6&"'!$B$11")="","",INDIRECT("'"&$B6&"'!$B$11")),"")) | R6: =IF($B6="","",IFERROR(IF(INDIRECT("'"&$B6&"'!$F$11")="","",INDIRECT("'"&$B6&"'!$F$11")),"")) | S6: =IF($B6="","",IFERROR(IF(INDIRECT("'"&$B6&"'!$J$11")="","",INDIRECT("'"&$B6&"'!$J$11")),"")) | T6: =IF($B6="","",IFERROR(IF(INDIRECT("'"&$B6&"'!$J$10")="","",INDIRECT("'"&$B6&"'!$J$10")),"")) | U6: =IF($B6="","",IFERROR(IF(INDIRECT("'"&$B6&"'!$F$10")="","",INDIRECT("'"&$B6&"'!$F$10")),"")) | V6: =IF('2027'!$G$10="","",'2027'!$G$10) -> Dispensa | X6: =IF($B6="","",IFERROR(IF(INDIRECT("'"&$B6&"'!$F$12")="","",INDIRECT("'"&$B6&"'!$F$12")),"")) | Y6: =IF($B6="","",IFERROR(IF(INDIRECT("'"&$B6&"'!$B$12")="","",INDIRECT("'"&$B6&"'!$B$12")),"")) | Z6: =IF($B6="","",IFERROR(IF(INDIRECT("'"&$B6&"'!$J$13")="","",INDIRECT("'"&$B6&"'!$J$13")),"")) | AB6: =IF($B6="","",IFERROR(IF(INDIRECT("'"&$B6&"'!$J$4")="","",INDIRECT("'"&$B6&"'!$J$4")),"")) | AC6: =IF($B6="","",2026) | AD6: =IF('2027'!$M$10="","",'2027'!$M$10) -> 1095.11 | AE6: =IF('2027'!$N$10="","",'2027'!$N$10) -> 12 | AF6: =IF('2027'!$O$10="","",'2027'!$O$10) -> 13141.32 | AI6: =IF('2027'!$Q$10="","",'2027'!$Q$10) -> 13443.69 | AJ6: =IF($B6="","",IFERROR(IF(INDIRECT("'"&$B6&"'!$D$21")="","",INDIRECT("'"&$B6&"'!$D$21")),"")) | AK6: =IF($B6="","",IFERROR(IF(INDIRECT("'"&$B6&"'!$E$21")="","",INDIRECT("'"&$B6&"'!$E$21")),"")) | AL6: =IF('2027'!$R$10="","",'2027'!$R$10) -> -302.37 | AM6: =IFERROR(AI6-AJ6,0) -> 13443.69 | AN6: =IFERROR(AJ6-AK6,0) -> 0 | AO6: =IF('2027'!$S$10="","",'2027'!$S$10) -> 1.0230091 | AP6: =IFERROR(AK6/AF6,0) -> 0 | AQ6: =IF($B6="","",IFERROR(IF(INDIRECT("'"&$B6&"'!$K$21")="","",INDIRECT("'"&$B6&"'!$K$21")),"")) | AR6: =IF('2027'!$T$10="","",'2027'!$T$10) -> - | AS6: =IF('2027'!$U$10="","",'2027'!$U$10) -> 0 | AT6: =IF($B6="","",IFERROR(IF(INDIRECT("'"&$B6&"'!$B$15")="","",INDIRECT("'"&$B6&"'!$B$15")),"")) | AV6: =IF($B6="","",IFERROR(IF(INDIRECT("'"&$B6&"'!$B$14")="","",INDIRECT("'"&$B6&"'!$B$14")),"")) | AW6: =IF($B6="","",AY6) | AX6: =IF($B6="","",IFERROR(IF(INDIRECT("'"&$B6&"'!$F$14")="","",INDIRECT("'"&$B6&"'!$F$14")),"")) | AY6: =IF($B6="","",IFERROR(IF(INDIRECT("'"&$B6&"'!$D$35")="","",INDIRECT("'"&$B6&"'!$D$35")),"")) | AZ6: =IF($B6="","",IFERROR(IF(INDIRECT("'"&$B6&"'!$J$14")="","",INDIRECT("'"&$B6&"'!$J$14")),"")) | BA6: =IF($B6="","",IFERROR(IF(INDIRECT("'"&$B6&"'!$I$21")="","",INDIRECT("'"&$B6&"'!$I$21")),"")) | BB6: =IF($B6="","",IFERROR(IF(INDIRECT("'"&$B6&"'!$C$67")="","",INDIRECT("'"&$B6&"'!$C$67")),"")) | BC6: =IF($B6="","",IFERROR(IF(INDIRECT("'"&$B6&"'!$D$68")="","",INDIRECT("'"&$B6&"'!$D$68")),"")) | BD6: =IFERROR(Z6+BB6-BC6,0) -> 0 | BE6: =IF($B6="","",IFERROR(IF(INDIRECT("'"&$B6&"'!$J$21")="","",INDIRECT("'"&$B6&"'!$J$21")),"")) | BF6: =IF($B6="","",IFERROR(IF(INDIRECT("'"&$B6&"'!$F$15")="","",INDIRECT("'"&$B6&"'!$F$15")),"")) | BG6: =IFERROR(N6-TODAY(),"") | BH6: =IF(N6="","",IF(AND(N6-TODAY()>=0,N6-TODAY()<=90),"Sim","Não")) -> #VALUE! | BI6: =IF(N6="","",IF(N6<TODAY(),"Sim","Não")) -> Não | BJ6: =IF(AF6=0,"",IF(IFERROR(AL6/AF6,0)<0.2,"Sim","Não")) -> Sim | BK6: =IF(AF6=0,"",IF(IFERROR(AK6/AF6,0)>0.9,"Sim","Não")) -> Não | BL6: =IF(AY6="","",IF(TODAY()-AY6>60,"Sim","Não")) | BM6: =IF('2027'!$V$10="","",'2027'!$V$10) -> Projeção anual para 2027. Referência de 2026: R$ 13.443,69 empenhados. O saldo compartilhado do elemento 3.3.90.36 foi registrado na linha do Contrato nº 39/2022 para não ser somado em duplicidade. | BN6: =IF($B6="","",IFERROR(IF(INDIRECT("'"&$B6&"'!$B$24")="","",INDIRECT("'"&$B6&"'!$B$24")),"")) | BO6: =IF($B6="","",IFERROR(IF(INDIRECT("'"&$B6&"'!$B$25")="","",INDIRECT("'"&$B6&"'!$B$25")),"")) | BP6: =IF($B6="","",IFERROR(IF(INDIRECT("'"&$B6&"'!$B$26")="","",INDIRECT("'"&$B6&"'!$B$26")),"")) | BQ6: =IF($B6="","",IFERROR(IF(INDIRECT("'"&$B6&"'!$B$27")="","",INDIRECT("'"&$B6&"'!$B$27")),"")) | BR6: =IF($B6="","",IFERROR(IF(INDIRECT("'"&$B6&"'!$B$28")="","",INDIRECT("'"&$B6&"'!$B$28")),"")) | BS6: =IF($B6="","",IF(AK6="","",IF(ROUND(AK6-SUM(BN6:BR6),2)>0,"Verificar — pagamento sem fonte",IF(ROUND(AK6-SUM(BN6:BR6),2)<0,"Verificar — fonte > pago","OK"))))
A7: =IF('2027'!$E$11="","",'2027'!$E$11) -> 92/2023 | C7: =IF('2027'!$B$11="","",'2027'!$B$11) -> 024.000150/2025-10 | D7: =IF('2027'!$C$11="","",'2027'!$C$11) -> FUNDO PENITENCIARIO DO ESTADO DE RONDONIA - FUPEN | E7: =IF('2027'!$D$11="","",'2027'!$D$11) -> 15.837.081/0001-56 | F7: =IF('2027'!$E$11="","",'2027'!$E$11) -> 92/2023 | G7: =IF('2027'!$F$11="","",'2027'!$F$11) -> Convênio Administrativo | H7: =IF('2027'!$H$11="","",'2027'!$H$11) -> Cooperação para disponibilização de 1 reeducando em regime aberto, em atividade de serviços gerais na SMD. | J7: =IF('2027'!$I$11="","",'2027'!$I$11) -> Contrato continuado | K7: =IF($B7="","",IFERROR(IF(INDIRECT("'"&$B7&"'!$B$10")="","",INDIRECT("'"&$B7&"'!$B$10")),"")) | L7: =IF('2027'!$J$11="","",'2027'!$J$11) -> Estimativo | M7: =IF('2027'!$K$11="","",'2027'!$K$11) -> 45234 | N7: =IF('2027'!$L$11="","",'2027'!$L$11) -> 46664 | O7: =IF($B7="","","SMD") | Q7: =IF($B7="","",IFERROR(IF(INDIRECT("'"&$B7&"'!$B$11")="","",INDIRECT("'"&$B7&"'!$B$11")),"")) | R7: =IF($B7="","",IFERROR(IF(INDIRECT("'"&$B7&"'!$F$11")="","",INDIRECT("'"&$B7&"'!$F$11")),"")) | S7: =IF($B7="","",IFERROR(IF(INDIRECT("'"&$B7&"'!$J$11")="","",INDIRECT("'"&$B7&"'!$J$11")),"")) | T7: =IF($B7="","",IFERROR(IF(INDIRECT("'"&$B7&"'!$J$10")="","",INDIRECT("'"&$B7&"'!$J$10")),"")) | U7: =IF($B7="","",IFERROR(IF(INDIRECT("'"&$B7&"'!$F$10")="","",INDIRECT("'"&$B7&"'!$F$10")),"")) | V7: =IF('2027'!$G$11="","",'2027'!$G$11) | X7: =IF($B7="","",IFERROR(IF(INDIRECT("'"&$B7&"'!$F$12")="","",INDIRECT("'"&$B7&"'!$F$12")),"")) | Y7: =IF($B7="","",IFERROR(IF(INDIRECT("'"&$B7&"'!$B$12")="","",INDIRECT("'"&$B7&"'!$B$12")),"")) | Z7: =IF($B7="","",IFERROR(IF(INDIRECT("'"&$B7&"'!$J$13")="","",INDIRECT("'"&$B7&"'!$J$13")),"")) | AB7: =IF($B7="","",IFERROR(IF(INDIRECT("'"&$B7&"'!$J$4")="","",INDIRECT("'"&$B7&"'!$J$4")),"")) | AC7: =IF($B7="","",2026) | AD7: =IF('2027'!$M$11="","",'2027'!$M$11) -> 2526.25 | AE7: =IF('2027'!$N$11="","",'2027'!$N$11) -> 12 | AF7: =IF('2027'!$O$11="","",'2027'!$O$11) -> 30315 | AI7: =IF('2027'!$Q$11="","",'2027'!$Q$11) -> 31365.67 | AJ7: =IF($B7="","",IFERROR(IF(INDIRECT("'"&$B7&"'!$D$21")="","",INDIRECT("'"&$B7&"'!$D$21")),"")) | AK7: =IF($B7="","",IFERROR(IF(INDIRECT("'"&$B7&"'!$E$21")="","",INDIRECT("'"&$B7&"'!$E$21")),"")) | AL7: =IF('2027'!$R$11="","",'2027'!$R$11) -> -1050.67 | AM7: =IFERROR(AI7-AJ7,0) -> 31365.67 | AN7: =IFERROR(AJ7-AK7,0) -> 0 | AO7: =IF('2027'!$S$11="","",'2027'!$S$11) -> 1.0346584 | AP7: =IFERROR(AK7/AF7,0) -> 0 | AQ7: =IF($B7="","",IFERROR(IF(INDIRECT("'"&$B7&"'!$K$21")="","",INDIRECT("'"&$B7&"'!$K$21")),"")) | AR7: =IF('2027'!$T$11="","",'2027'!$T$11) -> - | AS7: =IF('2027'!$U$11="","",'2027'!$U$11) -> 0 | AT7: =IF($B7="","",IFERROR(IF(INDIRECT("'"&$B7&"'!$B$15")="","",INDIRECT("'"&$B7&"'!$B$15")),"")) | AV7: =IF($B7="","",IFERROR(IF(INDIRECT("'"&$B7&"'!$B$14")="","",INDIRECT("'"&$B7&"'!$B$14")),"")) | AW7: =IF($B7="","",AY7) | AX7: =IF($B7="","",IFERROR(IF(INDIRECT("'"&$B7&"'!$F$14")="","",INDIRECT("'"&$B7&"'!$F$14")),"")) | AY7: =IF($B7="","",IFERROR(IF(INDIRECT("'"&$B7&"'!$D$35")="","",INDIRECT("'"&$B7&"'!$D$35")),"")) | AZ7: =IF($B7="","",IFERROR(IF(INDIRECT("'"&$B7&"'!$J$14")="","",INDIRECT("'"&$B7&"'!$J$14")),"")) | BA7: =IF($B7="","",IFERROR(IF(INDIRECT("'"&$B7&"'!$I$21")="","",INDIRECT("'"&$B7&"'!$I$21")),"")) | BB7: =IF($B7="","",IFERROR(IF(INDIRECT("'"&$B7&"'!$C$67")="","",INDIRECT("'"&$B7&"'!$C$67")),"")) | BC7: =IF($B7="","",IFERROR(IF(INDIRECT("'"&$B7&"'!$D$68")="","",INDIRECT("'"&$B7&"'!$D$68")),"")) | BD7: =IFERROR(Z7+BB7-BC7,0) -> 0 | BE7: =IF($B7="","",IFERROR(IF(INDIRECT("'"&$B7&"'!$J$21")="","",INDIRECT("'"&$B7&"'!$J$21")),"")) | BF7: =IF($B7="","",IFERROR(IF(INDIRECT("'"&$B7&"'!$F$15")="","",INDIRECT("'"&$B7&"'!$F$15")),"")) | BG7: =IFERROR(N7-TODAY(),"") -> 406 | BH7: =IF(N7="","",IF(AND(N7-TODAY()>=0,N7-TODAY()<=90),"Sim","Não")) -> Não | BI7: =IF(N7="","",IF(N7<TODAY(),"Sim","Não")) -> Não | BJ7: =IF(AF7=0,"",IF(IFERROR(AL7/AF7,0)<0.2,"Sim","Não")) -> Sim | BK7: =IF(AF7=0,"",IF(IFERROR(AK7/AF7,0)>0.9,"Sim","Não")) -> Não | BL7: =IF(AY7="","",IF(TODAY()-AY7>60,"Sim","Não")) | BM7: =IF('2027'!$V$11="","",'2027'!$V$11) -> Projeção anual para 2027. Referência de 2026: R$ 31.365,67 empenhados líquidos, incluída a despesa de exercício anterior vinculada ao instrumento. Não foi identificado saldo livre específico no elemento para registro nesta linha. | BN7: =IF($B7="","",IFERROR(IF(INDIRECT("'"&$B7&"'!$B$24")="","",INDIRECT("'"&$B7&"'!$B$24")),"")) | BO7: =IF($B7="","",IFERROR(IF(INDIRECT("'"&$B7&"'!$B$25")="","",INDIRECT("'"&$B7&"'!$B$25")),"")) | BP7: =IF($B7="","",IFERROR(IF(INDIRECT("'"&$B7&"'!$B$26")="","",INDIRECT("'"&$B7&"'!$B$26")),"")) | BQ7: =IF($B7="","",IFERROR(IF(INDIRECT("'"&$B7&"'!$B$27")="","",INDIRECT("'"&$B7&"'!$B$27")),"")) | BR7: =IF($B7="","",IFERROR(IF(INDIRECT("'"&$B7&"'!$B$28")="","",INDIRECT("'"&$B7&"'!$B$28")),"")) | BS7: =IF($B7="","",IF(AK7="","",IF(ROUND(AK7-SUM(BN7:BR7),2)>0,"Verificar — pagamento sem fonte",IF(ROUND(AK7-SUM(BN7:BR7),2)<0,"Verificar — fonte > pago","OK"))))
